<robot name="indenter">
	<link name="world">
        </link>

        <joint name="world_to_indenter" type="prismatic">
                <parent link="world"/>
                <child link="indenter"/>
                <origin rpy="0.0 0.0 0.0" xyz="0.0 0.0 0.0"/>
                <axis xyz="0 1 0"/>
                <dynamics damping="0.0" friction="0.0"/>
                <limit lower="0.0" upper="0.1" velocity="1e9" effort="1e9"/>
        </joint>

	<link name="indenter">
		<visual>
			<origin rpy="0.0 0.0 0.0" xyz="0.0 0.0 0.0"/>
			<geometry>
				<mesh filename="../../meshes/indenters/cylinder_short_7mm.obj"/>
			</geometry>
		</visual>
		<collision>
			<origin rpy="0.0 0.0 0.0" xyz="0.0 0.0 0.0"/>
			<geometry>
				<mesh filename="../../meshes/indenters/cylinder_short_7mm.obj"/>
			</geometry>
		</collision>
		<inertial>
			<origin rpy="0.0 0.0 0.0" xyz="0.0 -9.7773e-3 0.0"/>
			<mass value="0.00109215"/>
			<inertia ixx="3.36565e-8" iyy="9.34142e-9" izz="3.37229e-8" ixy="0.0" ixz="-4.47536e-15" iyz="0.0"/>
		</inertial>
	</link>
</robot>
