<robot name="indenter">
	<link name="world">
        </link>

        <joint name="world_to_indenter" type="prismatic">
                <parent link="world"/>
                <child link="indenter"/>
                <origin rpy="0.0 0.0 0.0" xyz="0.0 0.0 0.0"/>
                <axis xyz="0 1 0"/>
                <dynamics damping="0.0" friction="0.0"/>
                <limit lower="0.0" upper="0.1" velocity="1e9" effort="1e9"/>
        </joint>

	<link name="indenter">
		<visual>
			<origin rpy="0.0 0.0 0.0" xyz="0.0 0.0 0.0"/>
			<geometry>
				<mesh filename="../../meshes/indenters/cylinder_long_7mm.obj"/>
			</geometry>
		</visual>
		<collision>
			<origin rpy="0.0 0.0 0.0" xyz="0.0 0.0 0.0"/>
			<geometry>
				<mesh filename="../../meshes/indenters/cylinder_long_7mm.obj"/>
			</geometry>
		</collision>
		<inertial>
			<origin rpy="0.0 0.0 0.0" xyz="0.0 -7.78746e-3 0.0"/>
			<mass value="0.00319887"/>
			<inertia ixx="7.77398e-8" iyy="1.68013e-7" izz="2.20938e-7" ixy="3.87397e-16" ixz="-2.48829e-13" iyz="0.0"/>
			<inertia ixx="7.77398e-8" iyy="2.20938e-7" izz="1.68013e-7" ixy="2.48829e-13" ixz="3.87397e-16" iyz="0.0"/>
		</inertial>
	</link>
</robot>
