<robot name="indenter">
	<link name="world">
        </link>

        <joint name="world_to_indenter" type="prismatic">
                <parent link="world"/>
                <child link="indenter"/>
                <origin rpy="0.0 0.0 0.0" xyz="0.0 0.0 0.0"/>
                <axis xyz="0 1 0"/>
                <dynamics damping="0.0" friction="0.0"/>
                <limit lower="0.0" upper="0.1" velocity="1e9" effort="1e9"/>
        </joint>

	<link name="indenter">
		<visual>
			<origin rpy="0.0 0.0 0.0" xyz="0.0 0.0 0.0"/>
			<geometry>
				<mesh filename="../../meshes/indenters/sphere_14mm.obj"/>
			</geometry>
		</visual>
		<collision>
			<origin rpy="0.0 0.0 0.0" xyz="0.0 0.0 0.0"/>
			<geometry>
				<mesh filename="../../meshes/indenters/sphere_14mm.obj"/>
			</geometry>
		</collision>
		<inertial>
			<origin rpy="0.0 0.0 0.0" xyz="0.0 -8.64389e-3 0.0"/>
			<mass value="0.00224114"/>
			<inertia ixx="6.25553e-8" iyy="4.07645e-8" izz="6.25353e-8" ixy="0.0" ixz="4.69820e-15" iyz="0.0"/>
		</inertial>
	</link>
</robot>
